2025-05-30 22:31:51,892 - INFO - PyRC starting up...
2025-05-30 22:31:51,895 - INFO - PyRC Client Started
2025-05-30 22:31:51,895 - ERROR - An unexpected error occurred during logging setup: 'PyTermIRCClient' object has no attribute 'buffers'
2025-05-30 22:31:51,897 - CRITICAL - PyRC crashed: 'PyTermIRCClient' object has no attribute 'buffers'
Traceback (most recent call last):
  File "C:\Users\Administrator\ideas\pyRC\pyrc.py", line 293, in _setup_logging
    self._add_message_to_buffer("server", f"Logging to {log_file}")
    ~~~~~~~~~~~~~~~~~~~~~~~~~~~^^^^^^^^^^^^^^^^^^^^^^^^^^^^^^^^^^^^
  File "C:\Users\Administrator\ideas\pyRC\pyrc.py", line 525, in _add_message_to_buffer
    self._ensure_buffer_exists(buffer_name)  # Safe to call, checks existence
    ~~~~~~~~~~~~~~~~~~~~~~~~~~^^^^^^^^^^^^^
  File "C:\Users\Administrator\ideas\pyRC\pyrc.py", line 417, in _ensure_buffer_exists
    if name not in self.buffers:
                   ^^^^^^^^^^^^
AttributeError: 'PyTermIRCClient' object has no attribute 'buffers'

During handling of the above exception, another exception occurred:

Traceback (most recent call last):
  File "C:\Users\Administrator\ideas\pyRC\pyrc.py", line 1992, in <module>
    curses.wrapper(main_curses_app, parsed_args)
    ~~~~~~~~~~~~~~^^^^^^^^^^^^^^^^^^^^^^^^^^^^^^
  File "C:\Program Files\Python313\Lib\curses\__init__.py", line 94, in wrapper
    return func(stdscr, *args, **kwds)
  File "C:\Users\Administrator\ideas\pyRC\pyrc.py", line 1886, in main_curses_app
    client = PyTermIRCClient(stdscr, args)
  File "C:\Users\Administrator\ideas\pyRC\pyrc.py", line 115, in __init__
    self._setup_logging()
    ~~~~~~~~~~~~~~~~~~~^^
  File "C:\Users\Administrator\ideas\pyRC\pyrc.py", line 301, in _setup_logging
    self._add_message_to_buffer(
    ~~~~~~~~~~~~~~~~~~~~~~~~~~~^
        "server",
        ^^^^^^^^^
        f"Error: Unexpected error during logging setup: {e}",
        ^^^^^^^^^^^^^^^^^^^^^^^^^^^^^^^^^^^^^^^^^^^^^^^^^^^^^
        "ERROR",
        ^^^^^^^^
    )
    ^
  File "C:\Users\Administrator\ideas\pyRC\pyrc.py", line 525, in _add_message_to_buffer
    self._ensure_buffer_exists(buffer_name)  # Safe to call, checks existence
    ~~~~~~~~~~~~~~~~~~~~~~~~~~^^^^^^^^^^^^^
  File "C:\Users\Administrator\ideas\pyRC\pyrc.py", line 417, in _ensure_buffer_exists
    if name not in self.buffers:
                   ^^^^^^^^^^^^
AttributeError: 'PyTermIRCClient' object has no attribute 'buffers'
2025-05-30 22:31:51,910 - INFO - PyRC exited.
